Workbook

Sheet example - SUMMARY SHEET
C2: CRAZY ALMIRAH // AB-00123 // 10 PCS
C3: WOOD | I3: HARDWARE
C4: MANGO WOOD | I4: NAME | J4: QTY | K4: UNIT
C5: IN INCHES | D5: L | E5: W | F5: H | G5: CFT | I5: 11' HANDLE | J5: 20 | K5: PCS
C6: TOP | D6: 27 | E6: 38.4 | F6: 1 | G6: 6 | I6: 1.5' SCREW | J6: 300 | K6: PCS
C7: SIDE | D7: 63 | E7: 18 | F7: 1 | G7: 13.125 | I7: F35 NAILS | J7: 20 | K7: SET
C8: PARTITION | D8: 60 | E8: 19.2 | F8: 1 | G8: 6.6666667 | I8: 2' BRASS KNOB | J8: 10 | K8: PCS
C9: SHELF | D9: 18 | E9: 20.4 | F9: 1 | G9: 8.5 | I9: 60N PAPER | J9: 30 | K9: PCS
C10: BOTTOM | D10: 27 | E10: 19.2 | F10: 1 | G10: 3 | I10: 120N PAPER | J10: 30 | K10: PCS
C11: DOOR FRAME | D11: 60 | E11: 15.6 | F11: 1.5 | G11: 8.125 | I11: 10' CHAIN | J11: 10 | K11: PCS
E12: TOTAL | G12: =SUM(G6:G11) -> 45.416667
C13: OAK WOOD | I13: POLISHING
C14: IN INCHES | D14: L | E14: W | F14: SQFT | I14: NAME | J14: QTY | K14: UNIT
C15: DOOR PANEL | D15: 36 | E15: 19.2 | F15: 48 | I15: THINNER | J15: 20 | K15: LTR
D16: TOTAL | F16: =F15 -> 48 | I16: SEALER | J16: 20 | K16: LTR
I17: LACQUER | J17: 20 | K17: LTR
C18: IRON | I18: ROUGH CLOTH | J18: 20 | K18: PCS
C19: POWDERCOATED IRON FITTING | I19: SANDING PAPER | J19: 15 | K19: PCS
C20: PWDRFTG/133 | D20: 150 | E20: KGS
C21: TOTAL | D21: =D20 -> 150 | I21: PACKAGING
C22: POWDERCOATED IRON LEGS | I22: NAME | J22: QTY | K22: UNIT
C23: PWDRCTDLGS/1452 | D23: 10 | E23: PCS | I23: BUBBLE | J23: 0.88 | K23: MTR
C24: TOTAL | D24: =D23 -> 10 | I24: FOAM | J24: 0.78 | K24: MTR
C25: PLY | I25: CARTON 7PLY | J25: 1 | K25: PCS
C26: PLY 6MM | I26: CORNERS | J26: 8 | K26: PCS
C27: IN INCH | D27: L | E27: W | F27: SQFT
C28: BACK PLY | D28: 18 | E28: 32 | F28: 80
C29: BOTTOM PLY | D29: 19 | E29: 12 | F29: 79.2
D30: TOTAL | F30: =SUM(F28:F29) -> 159.2
C31: PLY 8MM
C32: IN CM | D32: L | E32: W | F32: SQMT
C33: BOTTOM SUPPORT | D33: 42 | E33: 30 | F33: 1.26
D34: TOTAL | F34: =F33 -> 1.26
C35: GLASS 4MM
C36: IN INCH | D36: L | E36: W | F36: SQFT
C37: DOOR GLASS | D37: 12 | E37: 18 | F37: 15
D38: TOTAL | F38: 15

Sheet example - COST DETAIL
C3: CRAZY ALMIRAH // AB-00123
C4: MAIN COMPONENTS
C5: WOOD
C6: MANGO WOOD | F6: CFT WISE COST
D7: ACTUALS | E7: IN INCHES | I7: COST | K7: USING CFT
D8: L | E8: W | F8: H | G8: QTY | H8: WASTAGE% | I8: L | J8: W | K8: H | L8: QTY | M8: CFT | N8: COST PER CFT | O8: COST
C9: TOP | D9: 25 | E9: 32 | F9: 1 | G9: 1 | H9: 20 | I9: 27 | J9: 38.4 | K9: 1 | L9: 1 | M9: =I9*J9*K9*L9/1728 -> 0.6 | N9: 560 | O9: =N9*M9 -> 336
C10: SIDE | D10: 59 | E10: 15 | F10: 1 | G10: 2 | H10: 20 | I10: 63 | J10: 18 | K10: 1 | L10: 2 | M10: =I10*J10*K10*L10/1728 -> 1.3125 | N10: 760 | O10: =N10*M10 -> 997.5
C11: PARTITION | D11: 56 | E11: 16 | F11: 1 | G11: 1 | H11: 20 | I11: 60 | J11: 19.2 | K11: 1 | L11: 1 | M11: =I11*J11*K11*L11/1728 -> 0.66666667 | N11: 760 | O11: =N11*M11 -> 506.66667
C12: SHELF | D12: 14 | E12: 17 | F12: 1 | G12: 4 | H12: 20 | I12: 18 | J12: 20.4 | K12: 1 | L12: 4 | M12: =I12*J12*K12*L12/1728 -> 0.85 | N12: 560 | O12: =N12*M12 -> 476
C13: BOTTOM | D13: 24 | E13: 16 | F13: 1 | G13: 1 | H13: 20 | I13: 27 | J13: 19.2 | K13: 1 | L13: 1 | M13: =I13*J13*K13*L13/1728 -> 0.3 | N13: 560 | O13: =N13*M13 -> 168
C14: DOOR FRAME | D14: 56 | E14: 13 | F14: 1.5 | G14: 1 | H14: 20 | I14: 60 | J14: 15.6 | K14: 1.5 | L14: 1 | M14: =I14*J14*K14*L14/1728 -> 0.8125 | N14: 760 | O14: =N14*M14 -> 617.5
M16: COMPONENT TOTAL | O16: =SUM(O9:O14) -> 3101.6667
C17: OAK WOOD | F17: SQFT WISE COST
D18: ACTUALS | E18: IN INCHES | I18: COST | K18: USING SQFT
D19: L | E19: W | F19: Q | H19: WASTAGE | I19: L | J19: W | K19: Q | L19: SQFT | M19: COST PER SQFT | N19: COST
C20: DOOR PANEL | D20: 34 | E20: 16 | F20: 1 | H20: 20 | I20: 36 | J20: =E20+20*E20/100 -> 19.2 | K20: 1 | L20: =I20*J20*K20/144 -> 4.8 | M20: 490 | N20: =L20*M20 -> 2352
L22: COMPONENT TOTAL | N22: =N20 -> 2352
C24: SUB COMPONENTS
C25: IRON
C26: POWDERCOATED IRON FITTING | F26: WEIGHT WISE
C27: NAME | D27: ACTUAL W | F27: WASTAGE | G27: REQ W | H27: UNIT | I27: COST PER W | J27: COST
C28: PWDRFTG/133 | D28: 14.38 | E28: KGS | F28: 0.0431 | G28: =D28*(1+F28) -> 14.999778 | H28: KGS | I28: 182 | J28: =I28*G28 -> 2729.9596
H30: COMPONENT TOTAL | J30: =J28 -> 2729.9596
C32: POWDERCOATED IRON LEGS | F32: QTY WISE
C33: NAME | F33: QTY | G33: UNIT | H33: COST PER UNIT | I33: COST
C34: PWDRCTDLGS/1452 | F34: 1 | G34: PCS | H34: 1200 | I34: 1200
G36: COMPONENT TOTAL | I36: =I34 -> 1200
C38: PLY
C39: PLY 6MM | E39: SQFT WISE COST
C40: (IN INCH) | D40: L | E40: W | F40: Q | G40: SQFT | H40: COST PER SQFT | I40: COST
C41: BACK PLY | D41: 18 | E41: 32 | F41: 2 | G41: =D41*E41*F41/144 -> 8 | H41: 30 | I41: =H41*G41 -> 240
C42: BOTTOM PLY | D42: 19 | E42: 12 | F42: 5 | G42: =D42*E42*F42/144 -> 7.9166667 | H42: 30 | I42: =H42*G42 -> 237.5
G44: COMPONENT TOTAL | I44: =SUM(I41:I42) -> 477.5
C45: PLY 8MM | E45: SQMT WISE COST
C46: (IN CM) | D46: L | E46: W | F46: Q | G46: SQM | H46: COST PER SQM | I46: COST
C47: BOTTOM SUPPORT | D47: 42 | E47: 30 | F47: 1 | G47: =D47*E47*F47/10000 -> 0.126 | H47: 960 | I47: =G47*H47 -> 120.96
G49: COMPONENT TOTAL | I49: =I47 -> 120.96
C51: GLASS 4MM | E51: SQFT WISE COST
C52: (IN INCH) | D52: L | E52: W | F52: Q | G52: =G40 -> SQFT | H52: =H40 -> COST PER SQFT | I52: COST
...

Sheet example - COST SUMMARY
B2: COMPONENTS | D2: TOTALS
B3: MAIN C | D3: =SUM('example - COST DETAIL'!O16,'example - COST DETAIL'!N22) -> 5453.6667
B4: SUB C | D4: =SUM('example - COST DETAIL'!J30,'example - COST DETAIL'!I36,'example - COST DETAIL'!I44,'example - COST DETAIL'!I49,'example - COST DETAIL'!I55) -> 4723.4196 | J4: FOB COST | L4: NON-FOB COST
B5: HARDWARE | D5: ='example - COST DETAIL'!G69 -> 665.6 | J5: =SUM(D9:E12) -> 19180.596 | L5: =SUM(D9:G9) -> 18104.081
B6: POLISHING | D6: ='example - COST DETAIL'!G79 -> 300
B7: PACKING | D7: ='example - COST DETAIL'!G88 -> 968.6
B8: LABOUR | D8: ='example - COST DETAIL'!E98 -> 1578
B9: EX FACTORY COST | D9: =SUM(D3:E8) -> 13689.286 | F9: =D9*(0.15) -> 2053.3929 | G9: =SUM(D9:F9)*(0.15) -> 2361.4019
B10: FORWARDING | D10: ='example - COST DETAIL'!E105 -> 814
B11: FACTORY EXPENSES 15% | D11: =SUM(D9:E10)*15/100 -> 2175.4929
B12: MARGIN 15% | D12: =SUM(D9:E11)*(15%) -> 2501.8169
